Workbook
Name _1B.05.M.010.0010: #REF!
Name _1B.05.M.010.0010: #REF!
Name _1B.05.M.010.0010: #REF!
Name _1B.05.M.010.0050: #REF!
Name _1B.05.M.010.0050: #REF!
Name _1B.05.M.010.0050: #REF!
Name _1B.05.M.0100.0010: #REF!
Name _1B.05.M.0100.0010: #REF!
Name _1B.05.M.020.0010: #REF!
Name _1B.05.M.020.0010: #REF!
Name _1B.05.M.020.0020: #REF!
Name _1B.05.M.020.0020: #REF!
Name _1B.05.M.020.0030: #REF!
Name _1B.05.M.020.0030: #REF!
Name _1B.05.M.020.0040: #REF!
Name _1B.05.M.020.0040: #REF!
Name _1B.05.M.030.0010: #REF!
Name _1B.05.M.030.0010: #REF!
Name _1B.05.M.030.0020: #REF!
Name _1B.05.M.030.0020: #REF!
Name _1B.05.M.040.0010: #REF!
Name _1B.05.M.040.0010: #REF!
Name _1B.05.M.050.0010: #REF!
Name _1B.05.M.050.0010: #REF!
Name _1B.05.M.050.0020: #REF!
Name _1B.05.M.050.0020: #REF!
Name _1B.05.M.050.0030: #REF!
Name _1B.05.M.050.0030: #REF!
Name _1B.05.M.060.0020: #REF!
Name _1B.05.M.060.0020: #REF!
Name _1B.05.M.060.0100: #REF!
Name _1B.05.M.060.0100: #REF!
Name _1B.05.M.070.0010: #REF!
Name _1B.05.M.070.0010: #REF!
Name _1B.05.M.070.0020: #REF!
Name _1B.05.M.070.0020: #REF!
Name _1B.05.M.070.0030: #REF!
Name _1B.05.M.070.0030: #REF!
Name _1B.05.M.070.0040: #REF!
Name _1B.05.M.070.0040: #REF!
Name _1B.05.M.070.0050: #REF!
Name _1B.05.M.070.0050: #REF!
Name _1B.05.M.080.0010: #REF!
Name _1B.05.M.080.0010: #REF!
Name _1B.05.M.090.0010: #REF!
Name _1B.05.M.090.0010: #REF!
Name _1B.09.P.010.0010: #REF!
Name _1B.09.P.010.0010: #REF!
Name _1B.09.P.010.0020: #REF!
Name _1B.09.P.010.0020: #REF!
Name _1B.09.P.010.0030: #REF!
Name _1B.09.P.010.0030: #REF!
Name _1B.09.P.010.0040: #REF!
Name _1B.09.P.010.0040: #REF!
Name _1B.09.P.010.0050: #REF!
Name _1B.09.P.010.0050: #REF!
Name _1B.09.P.010.0060: #REF!
Name _1B.09.P.010.0060: #REF!
Name _1B.09.P.010.0070: #REF!
Name _1B.09.P.010.0070: #REF!

Sheet DB
A1: ='Weekly Progress Report'!$A$1 -> MODON - Weekly Progress Report - Construction Projects
B2: ='Weekly Progress Report'!$A$2 -> Contract General Information | J2: ='Weekly Progress Report'!G2 -> Key Dates | U2: ='Weekly Progress Report'!$L$2 -> Cost Summary (SR) | AD2: ='Weekly Progress Report'!$T$2 -> Performance Summary | AP2: ='Weekly Progress Report'!A54 -> Shop Drawings | AT2: ='Weekly Progress Report'!A63 -> Material Approval | AW2: ='Weekly Progress Report'!A72 -> Procurement Summary | BD2: ='Weekly Progress Report'!K54 -> Quality Reports | BT2: ='Weekly Progress Report'!K62 -> Key Submittals Approval Status | CD2: ='Weekly Progress Report'!K68 -> Invoices Summary | CR2: ='Weekly Progress Report'!K76 -> Resources at Site | CY2: ='Weekly Progress Report'!V54 -> Safety Statistics | FK2: ='Weekly Progress Report'!A81 -> Primavera P6 Schedule Status | FS2: ='Weekly Progress Report'!A90 -> Weekly Prgoress Photos
A3: ='Weekly Progress Report'!AE1 -> Data Date | B3: ='Weekly Progress Report'!A3 -> Project Name | C3: ='Weekly Progress Report'!A4 -> Project ID | D3: ='Weekly Progress Report'!A5 -> Contractor | E3: ='Weekly Progress Report'!A6 -> Consultant | F3: ='Weekly Progress Report'!D4 -> Stage | G3: ='Weekly Progress Report'!D5 -> Status | H3: ='Weekly Progress Report'!D6 -> Modon PM | I3: ='Weekly Progress Report'!Z2 -> Project Scope | J3: ='Weekly Progress Report'!G3 -> Contract Award | K3: ='Weekly Progress Report'!G4 -> Contract Sign | L3: ='Weekly Progress Report'!G5 -> Site Handover | M3: ='Weekly Progress Report'!G6 -> Original Completion | N3: ='Weekly Progress Report'!$H$3 -> Contract Award (Hijri) | O3: ='Weekly Progress Report'!$H$4 -> Contract Sign (Hijri) | P3: ='Weekly Progress Report'!$H$5 -> Site Handover (Hijri) | Q3: ='Weekly Progress Report'!$H$6 -> Original Completion (Hijri) | R3: ='Weekly Progress Report'!$J$3 -> Revised Completion | S3: ='Weekly Progress Report'!$J$4 -> Committed Completion | T3: ='Weekly Progress Report'!$J$5 -> Forecast Completion | U3: ='Weekly Progress Report'!$L$3 -> Original Contract Value | V3: ='Weekly Progress Report'!$L$4 -> Revised Contract Value | W3: ='Weekly Progress Report'!$L$5 -> Estimate At Completion Value | X3: ='Weekly Progress Report'!$L$6 -> Potential Changes | Y3: ='Weekly Progress Report'!$P$3 -> O&M Value (if any) | Z3: ='Weekly Progress Report'!$P$4 -> Submitted Invoices (Gross Value) | AA3: ='Weekly Progress Report'!$P$5 -> Penalities | AB3: ='Weekly Progress Report'!$P$6 -> FIR Value (Todate) | AC3: Original Plan Value | AD3: ='Weekly Progress Report'!$T$3 -> Plan Value | AE3: ='Weekly Progress Report'!$T$4 -> Earn Value | AF3: ='Weekly Progress Report'!$V$3 -> Phys. Plan Value | AG3: ='Weekly Progress Report'!$V$4 -> Phys. Earn Value | AH3: ='Weekly Progress Report'!$X$3 -> Quality Score | AI3: ='Weekly Progress Report'!$X$5 -> Safety Score | AJ3: Weekly PV (SAR) | AK3: Weekly EV (SAR) | AL3: Weekly PV % | AM3: Weekly PV % | AN3: Weekly Phys PV% | AO3: Weekly Phys PV% | AP3: Total SD Planned | AQ3: SD Remaining | AR3: SD Pending | AS3: Total SD Submittals | AT3: Planned Materials Approv | AU3: Material Pending Approval | AV3: Materila Total Submittals | AW3: ='Weekly Progress Report'!C73 -> Total Materials | AX3: ='Weekly Progress Report'!D73 -> Total Number of P.O. | AY3: ='Weekly Progress Report'!E73 -> Actual P.O. To Date | AZ3: ='Weekly Progress Report'!F73 -> Remaining P.O | BA3: ='Weekly Progress Report'!G73 -> Material on Site | BB3: ='Weekly Progress Report'!#REF! -> #REF! | BC3: ='Weekly Progress Report'!H73 -> Material Delivery Completion (Date) | BD3: ="NCR "&'Weekly Progress Report'!M55 -> NCR Issued | BE3: ="NCR "&'Weekly Progress Report'!N55 -> NCR Closed | BF3: ="NCR "&'Weekly Progress Report'!O55 -> NCR Pending | BG3: ="NCR "&'Weekly Progress Report'!P55 -> NCR Avg. Closing (Days) | BH3: ="SIR "&'Weekly Progress Report'!M55 -> SIR Issued | BI3: ="SIR "&'Weekly Progress Report'!N55 -> SIR Closed | BJ3: ="SIR "&'Weekly Progress Report'!O55 -> SIR Pending | BK3: ="SIR "&'Weekly Progress Report'!P55 -> SIR Avg. Closing (Days) | BL3: ="MIR "&'Weekly Progress Report'!M55 -> MIR Issued | BM3: ="MIR "&'Weekly Progress Report'!N55 -> MIR Closed | BN3: ="MIR "&'Weekly Progress Report'!O55 -> MIR Pending | BO3: ="MIR "&'Weekly Progress Report'!P55 -> MIR Avg. Closing (Days) | BP3: ="FIR "&'Weekly Progress Report'!M55 -> FIR Issued | BQ3: ="FIR "&'Weekly Progress Report'!N55 -> FIR Closed | BR3: ="FIR "&'Weekly Progress Report'!O55 -> FIR Pending | BS3: ="FIR "&'Weekly Progress Report'!P55 -> FIR Avg. Closing (Days) | BT3: ='Weekly Progress Report'!K63 -> 1 Quality Plan Approval | BU3: ='Weekly Progress Report'!K64 -> 2 Quality Plan Last Up | BV3: ='Weekly Progress Report'!K65 -> 3 Safety Plan Approval | BW3: ='Weekly Progress Report'!K66 -> 4 Safety Plan Last Up | BX3: ='Weekly Progress Report'!K67 -> 5 Construction Plan Approval | BY3: ='Weekly Progress Report'!P63 -> 6 Baseline Approval | BZ3: ='Weekly Progress Report'!P64 -> 7 No of Approved Version of Schedule | CA3: ='Weekly Progress Report'!P65 -> 8 Last Approved Schedule | CB3: ='Weekly Progress Report'!P66 -> 9 BOQ Approval Date | CC3: ='Weekly Progress Report'!P67 -> 10 No of Approved Version of BOQ | CD3: ='Weekly Progress Report'!K69 -> Total Submitted Invoices | CE3: ='Weekly Progress Report'!K70 -> PM Approved Invoices | CF3: ='Weekly Progress Report'!K71 -> No of Paid Invoices | CG3: ='Weekly Progress Report'!K72 -> No of Pending Invoices | CH3: ='Weekly Progress Report'!K73 -> Advance Payment % | CI3: ='Weekly Progress Report'!K74 -> Retention % | CJ3: ='Weekly Progress Report'!K75 -> Deduction / Penalties % | CK3: ='Weekly Progress Report'!N69 -> Submitted Invoices (SAR) | CL3: ='Weekly Progress Report'!N70 -> PM Approved Invoices (SAR) | CM3: ='Weekly Progress Report'!N71 -> Paid Invoices (SAR) | CN3: ='Weekly Progress Report'!N72 -> Last Submitted Period | CO3: ='Weekly Progress Report'!N73 -> Advance Payment (SAR) | CP3: ='Weekly Progress Report'!N74 -> Retention (SAR) | CQ3: ='Weekly Progress Report'!N75 -> Deduction / Penalties (SAR) | CR3: Planned Head Count | CS3: Actual Head Count | CT3: Saudi Staff | CU3: Labor Planned | CV3: Labor Actual | CW3: Equipment Planned | CX3: Equipment Actual | CY3: ="This Week "&'Weekly Progress Report'!W57 -> This Week Total Hours Worked | CZ3: ="This Week "&'Weekly Progress Report'!W58 -> This Week Safe Hours Worked | DA3: ="This Week "&'Weekly Progress Report'!W59 -> This Week LTI | DB3: ="This Week "&'Weekly Progress Report'!W60 -> This Week MTC (Healed w/o Disability) | DC3: ="This Week "&'Weekly Progress Report'!W61 -> This Week MTC (Healed w/ Disability) | DD3: ="This Week "&'Weekly Progress Report'!W62 -> This Week Near Miss | DE3: ="This Week "&'Weekly Progress Report'!W63 -> This Week First Aid Cases | DF3: ="This Week "&'Weekly Progress Report'!W64 -> This Week Fatality | DG3: ="This Week "&'Weekly Progress Report'!W65 -> This Week Fire Incident Cases | DH3: ="This Week "&'Weekly Progress Report'!W66 -> This Week Vehicle Incident | DI3: ="This Week "&'Weekly Progress Report'!W67 -> This Week Property Damages | DJ3: ="This Week "&'Weekly Progress Report'!W68 -> This Week Induction Training - Sessions(Headcount) | DK3: ="This Week "&'Weekly Progress Report'!W69 -> This Week No.of Internal Training - Sessions(Headcount) | DL3: ="This Week "&'Weekly Progress Report'!W70 -> This Week No.of Internal Audit | DM3: ="This Week "&'Weekly Progress Report'!W71 -> This Week No. of Toolbox Talks - Sessions(Headcount) | DN3: ="This Week "&'Weekly Progress Report'!W72 -> This Week Safety Awards/Incentives | DO3: ="This Month "&'Weekly Progress Report'!W57 -> This Month Total Hours Worked | DP3: ="This Month "&'Weekly Progress Report'!W58 -> This Month Safe Hours Worked | DQ3: ="This Month "&'Weekly Progress Report'!W59 -> This Month LTI | DR3: ="This Month "&'Weekly Progress Report'!W60 -> This Month MTC (Healed w/o Disability) | DS3: ="This Month "&'Weekly Progress Report'!W61 -> This Month MTC (Healed w/ Disability) | DT3: ="This Month "&'Weekly Progress Report'!W62 -> This Month Near Miss | DU3: ="This Month "&'Weekly Progress Report'!W63 -> This Month First Aid Cases | DV3: ="This Month "&'Weekly Progress Report'!W64 -> This Month Fatality | DW3: ="This Month "&'Weekly Progress Report'!W65 -> This Month Fire Incident Cases | DX3: ="This Month "&'Weekly Progress Report'!W66 -> This Month Vehicle Incident | DY3: ="This Month "&'Weekly Progress Report'!W67 -> This Month Property Damages | DZ3: ="This Month "&'Weekly Progress Report'!W68 -> This Month Induction Training - Sessions(Headcount) | EA3: ="This Month "&'Weekly Progress Report'!W69 -> This Month No.of Internal Training - Sessions(Headcount) | EB3: ="This Month "&'Weekly Progress Report'!W70 -> This Month No.of Internal Audit | EC3: ="This Month "&'Weekly Progress Report'!W71 -> This Month No. of Toolbox Talks - Sessions(Headcount) | ED3: ="This Month "&'Weekly Progress Report'!W72 -> This Month Safety Awards/Incentives | EE3: ="YTD "&'Weekly Progress Report'!W57 -> YTD Total Hours Worked | EF3: ="YTD "&'Weekly Progress Report'!W58 -> YTD Safe Hours Worked | EG3: ="YTD "&'Weekly Progress Report'!W59 -> YTD LTI | EH3: ="YTD "&'Weekly Progress Report'!W60 -> YTD MTC (Healed w/o Disability) | EI3: ="YTD "&'Weekly Progress Report'!W61 -> YTD MTC (Healed w/ Disability) | EJ3: ="YTD "&'Weekly Progress Report'!W62 -> YTD Near Miss | EK3: ="YTD "&'Weekly Progress Report'!W63 -> YTD First Aid Cases | EL3: ="YTD "&'Weekly Progress Report'!W64 -> YTD Fatality | EM3: ="YTD "&'Weekly Progress Report'!W65 -> YTD Fire Incident Cases | EN3: ="YTD "&'Weekly Progress Report'!W66 -> YTD Vehicle Incident | EO3: ="YTD "&'Weekly Progress Report'!W67 -> YTD Property Damages | EP3: ="YTD "&'Weekly Progress Report'!W68 -> YTD Induction Training - Sessions(Headcount) | EQ3: ="YTD "&'Weekly Progress Report'!W69 -> YTD No.of Internal Training - Sessions(Headcount) | ER3: ="YTD "&'Weekly Progress Report'!W70 -> YTD No.of Internal Audit | ES3: ="YTD "&'Weekly Progress Report'!W71 -> YTD No. of Toolbox Talks - Sessions(Headcount) | ET3: ="YTD "&'Weekly Progress Report'!W72 -> YTD Safety Awards/Incentives | EU3: ="Cum "&'Weekly Progress Report'!W57 -> Cum Total Hours Worked | EV3: ="Cum "&'Weekly Progress Report'!W58 -> Cum Safe Hours Worked | EW3: ="Cum "&'Weekly Progress Report'!W59 -> Cum LTI | EX3: ="Cum "&'Weekly Progress Report'!W60 -> Cum MTC (Healed w/o Disability) | EY3: ="Cum "&'Weekly Progress Report'!W61 -> Cum MTC (Healed w/ Disability) | EZ3: ="Cum "&'Weekly Progress Report'!W62 -> Cum Near Miss | FA3: ="Cum "&'Weekly Progress Report'!W63 -> Cum First Aid Cases | FB3: ="Cum "&'Weekly Progress Report'!W64 -> Cum Fatality | FC3: ="Cum "&'Weekly Progress Report'!W65 -> Cum Fire Incident Cases | FD3: ="Cum "&'Weekly Progress Report'!W66 -> Cum Vehicle Incident | FE3: ="Cum "&'Weekly Progress Report'!W67 -> Cum Property Damages | FF3: ="Cum "&'Weekly Progress Report'!W68 -> Cum Induction Training - Sessions(Headcount) | FG3: ="Cum "&'Weekly Progress Report'!W69 -> Cum No.of Internal Training - Sessions(Headcount) | FH3: ="Cum "&'Weekly Progress Report'!W70 -> Cum No.of Internal Audit | FI3: ="Cum "&'Weekly Progress Report'!W71 -> Cum No. of Toolbox Talks - Sessions(Headcount) | FJ3: ="Cum "&'Weekly Progress Report'!W72 -> Cum Safety Awards/Incentives | FK3: ='Weekly Progress Report'!A84 -> Total Act. | FL3: ='Weekly Progress Report'!B84 -> Not Started | FM3: ='Weekly Progress Report'!C84 -> In Progress | FN3: ='Weekly Progress Report'!D84 -> Completed | FO3: Critical Path Act.Last Week | FP3: Critical Path Act.This Week | FQ3: Failed start Last Week | FR3: Failed start This Week | FS3: ='Weekly Progress Report'!B92 -> 0 | FT3: ='Weekly Progress Report'!D92 -> 0 | FU3: ='Weekly Progress Report'!F92 -> 0 | FV3: ='Weekly Progress Report'!#REF! -> #REF! | FW3: ='Weekly Progress Report'!I92 -> 0 | FX3: ='Weekly Progress Report'!K92 -> 0 | FY3: ='Weekly Progress Report'!M92 -> 0 | FZ3: ='Weekly Progress Report'!N92 -> 0 | GA3: ='Weekly Progress Report'!O92 -> 0
A4: ='Weekly Progress Report'!AF1 -> 46286 | B4: ='Weekly Progress Report'!B3 -> Improvement of Waad Al Shamal Industrial City Fence & Gates | C4: ='Weekly Progress Report'!B4 -> WAS1-05-006 | D4: ='Weekly Progress Report'!B5 -> Hamza Mohammad Alderi Construction Co. | E4: ='Weekly Progress Report'!B6 -> Consolidated Consultants Group | F4: ='Weekly Progress Report'!E4 -> Construction | G4: ='Weekly Progress Report'!E5 -> Active | H4: ='Weekly Progress Report'!E6 -> Muhammed H. Al-Essa | I4: ='Weekly Progress Report'!Z3 -> #REF! | J4: ='Weekly Progress Report'!#REF! -> #REF! | K4: ='Weekly Progress Report'!#REF! -> #REF! | L4: ='Weekly Progress Report'!#REF! -> #REF! | M4: ='Weekly Progress Report'!#REF! -> #REF! | N4: ='Weekly Progress Report'!$I$3 -> 46107 | O4: ='Weekly Progress Report'!$I$4 -> 46107 | P4: ='Weekly Progress Report'!$I$5 -> 46148 | Q4: ='Weekly Progress Report'!$I$6 -> 46300 | R4: ='Weekly Progress Report'!$K$3 -> 46300 | S4: ='Weekly Progress Report'!$K$4 -> 46300 | T4: ='Weekly Progress Report'!$K$5 -> 46300 | U4: ='Weekly Progress Report'!$N$3 -> 15898659 | V4: ='Weekly Progress Report'!$N$4 -> 15898659 | W4: ='Weekly Progress Report'!$N$5 -> 15898659 | X4: ='Weekly Progress Report'!$N$6 -> 0 | Y4: ='Weekly Progress Report'!$R$3 -> 0 | Z4: ='Weekly Progress Report'!$R$4 -> 0 | AA4: ='Weekly Progress Report'!$R$5 -> 0 | AB4: ='Weekly Progress Report'!$R$6 -> 0 | AC4: ='Weekly Progress Report'!$I$23 -> 12162388 | AD4: ='Weekly Progress Report'!$U$3 -> 0.76499456 | AE4: ='Weekly Progress Report'!$U$4 -> 0.39339486 | AF4: ='Weekly Progress Report'!$W$3 -> 0.63904558 | AG4: ='Weekly Progress Report'!$W$4 -> 0.20345145 | AH4: ='Weekly Progress Report'!$Y$3 -> 0.86206897 | AI4: ='Weekly Progress Report'!$Y$5 -> 0.85 | AJ4: ='Weekly Progress Report'!$E$23 -> 1952900.5 | AK4: ='Weekly Progress Report'!$F$23 -> 0 | AL4: =AJ4/V4 -> 0.12283429 | AM4: =AK4/V4 -> 0 | AN4: ='Weekly Progress Report'!R23 -> 2373 | AO4: ='Weekly Progress Report'!S23 -> 0 | AP4: ='Weekly Progress Report'!C62 -> 35 | AQ4: ='Weekly Progress Report'!H62 -> 0 | AR4: ='Weekly Progress Report'!I62 -> 1 | AS4: ='Weekly Progress Report'!J62 -> 35 | AT4: ='Weekly Progress Report'!C71 -> 90 | AU4: ='Weekly Progress Report'!I71 -> 0 | AV4: ='Weekly Progress Report'!J71 -> 90 | AW4: ='Weekly Progress Report'!C80 | AX4: ='Weekly Progress Report'!D80 | AY4: ='Weekly Progress Report'!E80 | AZ4: ='Weekly Progress Report'!F80 | BA4: ='Weekly Progress Report'!G80 | BB4: ='Weekly Progress Report'!#REF! -> #REF! | BC4: ='Weekly Progress Report'!H80 -> 0 | BD4: ='Weekly Progress Report'!M58 -> 0 | BE4: ='Weekly Progress Report'!N58 -> 0 | BF4: ='Weekly Progress Report'!O58 -> 0 | BG4: ='Weekly Progress Report'!P58 -> 0 | BH4: ='Weekly Progress Report'!M59 -> 0 | BI4: ='Weekly Progress Report'!N59 -> 0 | BJ4: ='Weekly Progress Report'!O59 -> 0 | BK4: ='Weekly Progress Report'!P59 -> 0 | BL4: ='Weekly Progress Report'!M60 -> 24 | BM4: ='Weekly Progress Report'!N60 -> 5 | BN4: ='Weekly Progress Report'!O60 -> 0 | BO4: ='Weekly Progress Report'!P60 -> 0 | BP4: ='Weekly Progress Report'!M61 -> 229 | BQ4: ='Weekly Progress Report'!N61 -> 36 | BR4: ='Weekly Progress Report'!O61 -> 0 | BS4: ='Weekly Progress Report'!P61 -> 0 | BT4: ='Weekly Progress Report'!N63 -> 46159 | BU4: ='Weekly Progress Report'!N64 -> 46159 | BV4: ='Weekly Progress Report'!N65 -> 46161 | BW4: ='Weekly Progress Report'!N66 -> 46161 | BX4: ='Weekly Progress Report'!N67 -> 46167 | BY4: ='Weekly Progress Report'!T63 -> 46162 | BZ4: ='Weekly Progress Report'!T64 -> 46162 | CA4: ='Weekly Progress Report'!T65 -> 46162 | CB4: ='Weekly Progress Report'!T66 -> 46148 | CC4: ='Weekly Progress Report'!T67 -> 46148 | CD4: ='Weekly Progress Report'!M69 -> 0 | CE4: ='Weekly Progress Report'!M70 -> 0 | CF4: ='Weekly Progress Report'!M71 -> 0 | CG4: ='Weekly Progress Report'!M72 -> 0 | CH4: ='Weekly Progress Report'!M73 -> 0 | CI4: ='Weekly Progress Report'!M74 -> 0 | CJ4: ='Weekly Progress Report'!M75 -> 0 | CK4: ='Weekly Progress Report'!Q69 -> 3502841.3 | CL4: ='Weekly Progress Report'!Q70 -> 0 | CM4: ='Weekly Progress Report'!Q71 -> 0 | CN4: ='Weekly Progress Report'!Q72 -> 46275 | CO4: ='Weekly Progress Report'!Q73 -> 0 | CP4: ='Weekly Progress Report'!Q74 -> 0 | CQ4: ='Weekly Progress Report'!Q75 -> 0 | CR4: ='Weekly Progress Report'!K79 -> 8 | CS4: ='Weekly Progress Report'!L79 -> 11 | CT4: ='Weekly Progress Report'!N79 -> 2 | CU4: ='Weekly Progress Report'!O79 -> 15 | CV4: ='Weekly Progress Report'!P79 -> 108 | CW4: ='Weekly Progress Report'!S89 -> 3 | CX4: ='Weekly Progress Report'!T89 -> 8 | CY4: ='Weekly Progress Report'!Y57 -> 5562 | CZ4: ='Weekly Progress Report'!Y58 -> 5562 | DA4: ='Weekly Progress Report'!Y59 -> 0 | DB4: ='Weekly Progress Report'!Y60 -> 0 | DC4: ='Weekly Progress Report'!Y61 -> 0 | DD4: ='Weekly Progress Report'!Y62 -> 0 | DE4: ='Weekly Progress Report'!Y63 -> 0 | DF4: ='Weekly Progress Report'!Y64 -> 0 | DG4: ='Weekly Progress Report'!Y65 -> 0 | DH4: ='Weekly Progress Report'!Y66 -> 0 | DI4: ='Weekly Progress Report'!Y67 -> 0 | DJ4: ='Weekly Progress Report'!Y68 -> 3(6) | DK4: ='Weekly Progress Report'!Y69 -> 0 | DL4: ='Weekly Progress Report'!Y70 -> 0 | DM4: ='Weekly Progress Report'!Y71 -> 1(8) | DN4: ='Weekly Progress Report'!Y72 -> 0 | DO4: ='Weekly Progress Report'!AA57 -> 16470 | DP4: ='Weekly Progress Report'!AA58 -> 16470 | DQ4: ='Weekly Progress Report'!AA59 -> 0 | DR4: ='Weekly Progress Report'!AA60 -> 0 | DS4: ='Weekly Progress Report'!AA61 -> 0 | DT4: ='Weekly Progress Report'!AA62 -> 0 | DU4: ='Weekly Progress Report'!AA63 -> 0 | DV4: ='Weekly Progress Report'!AA64 -> 0 | DW4: ='Weekly Progress Report'!AA65 -> 0 | DX4: ='Weekly Progress Report'!AA66 -> 0 | DY4: ='Weekly Progress Report'!AA67 -> 0 | DZ4: ='Weekly Progress Report'!AA68 -> 9(21) | EA4: ='Weekly Progress Report'!AA69 -> 0 | EB4: ='Weekly Progress Report'!AA70 -> 0 | EC4: ='Weekly Progress Report'!AA71 -> 3(27) | ED4: ='Weekly Progress Report'!AA72 -> 0 | EE4: ='Weekly Progress Report'!AB57 -> 30524 | EF4: ='Weekly Progress Report'!AB58 -> 30524 | EG4: ='Weekly Progress Report'!AB59 -> 0 | EH4: ='Weekly Progress Report'!AB60 -> 0 | EI4: ='Weekly Progress Report'!AB61 -> 0 | EJ4: ='Weekly Progress Report'!AB62 -> 0 | EK4: ='Weekly Progress Report'!AB63 -> 0 | EL4: ='Weekly Progress Report'!AB64 -> 0 | EM4: ='Weekly Progress Report'!AB65 -> 0 | EN4: ='Weekly Progress Report'!AB66 -> 0 | EO4: ='Weekly Progress Report'!AB67 -> 0 | EP4: ='Weekly Progress Report'!AB68 -> 23(137) | EQ4: ='Weekly Progress Report'!AB69 -> 2(14) | ER4: ='Weekly Progress Report'!AB70 -> 3 | ES4: ='Weekly Progress Report'!AB71 -> 17(230) | ET4: ='Weekly Progress Report'!AB72 -> 0 | EU4: ='Weekly Progress Report'!AC57 -> 30524 | EV4: ='Weekly Progress Report'!AC58 -> 30524 | EW4: ='Weekly Progress Report'!AC59 -> 0 | EX4: ='Weekly Progress Report'!AC60 -> 0 | EY4: ='Weekly Progress Report'!AC61 -> 0 | EZ4: ='Weekly Progress Report'!AC62 -> 0 | FA4: ='Weekly Progress Report'!AC63 -> 0 | FB4: ='Weekly Progress Report'!AC64 -> 0 | FC4: ='Weekly Progress Report'!AC65 -> 0 | FD4: ='Weekly Progress Report'!AC66 -> 0 | FE4: ='Weekly Progress Report'!AC67 -> 0 | FF4: ='Weekly Progress Report'!AC68 -> 23(137) | FG4: ='Weekly Progress Report'!AC69 -> 2(14) | FH4: ='Weekly Progress Report'!AC70 -> 3 | FI4: ='Weekly Progress Report'!AC71 -> 17(230) | FJ4: ='Weekly Progress Report'!AC72 | FK4: ='Weekly Progress Report'!A85 -> 554 | FL4: ='Weekly Progress Report'!B85 -> 390 | FM4: ='Weekly Progress Report'!C85 -> 63 | FN4: ='Weekly Progress Report'!D85 -> 101 | FO4: ='Weekly Progress Report'!A89 -> 0 | FP4: ='Weekly Progress Report'!B89 -> 0 | FQ4: ='Weekly Progress Report'!#REF! -> #REF! | FR4: ='Weekly Progress Report'!H89 -> 28 | FS4: ='Weekly Progress Report'!B97 -> 0 | FT4: ='Weekly Progress Report'!D97 -> 0 | FU4: ='Weekly Progress Report'!F97 -> 0 | FV4: ='Weekly Progress Report'!#REF! -> #REF! | FW4: ='Weekly Progress Report'!I97 -> 0 | FX4: ='Weekly Progress Report'!K97 -> 0 | FY4: ='Weekly Progress Report'!M97 -> 0 | FZ4: ='Weekly Progress Report'!N97 -> 0 | GA4: ='Weekly Progress Report'!O97 -> 0

Sheet General Information
A1: Weekly Progress Report - Construction Projects | K1: Data Date | L1: 46286
A2: Contract General Information
A3: Project Name | C3: Improvement of Waad Al Shamal Industrial City Fence & Gates
A4: Project ID | C4: WAS1-05-006
A5: Contractor | C5: Hamza Mohammad Alderi Construction Co.
A6: Consultant | C6: Consolidated Consultants Group
A7: Stage | C7: Construction
A8: Status | C8: Active
A9: Modon PM | C9: Muhammed H. Al-Essa
A11: Key Dates
A12: Contract Award Date | C12: 46107
A13: Contract Sign Date | C13: 46107
A14: Site Handover Date | C14: 46148
A15: Original Completion | C15: 46300
A16: Contract Award Date (Hijri) | C16: =C12 -> 46107
A17: Contract Sign Date (Hijri) | C17: =C13 -> 46107
A18: Site Handover Date (Hijri) | C18: =C14 -> 46148
A19: Original Completion (Hijri) | C19: =C15 -> 46300
A20: Revised Completion Date | C20: 46300
A21: Committed Completion Date | C21: 46300
A22: Forecast Completion | C22: 46300 | K22: =C15-C14 -> 152
A23: Variance | C23: =C20-C22 -> 0 | K23: =L1-C14 -> 138 | L23: =K23/K22 -> 0.90789474
A25: Key Project Submittals | C25: Submission Date | D25: Days taken to approve orginal plan from site handover date
A26: Quality Plan submission | C26: 46159 | D26: =C26-C14 -> 11
A27: Quality Plan approval | C27: 46159
A28: Quality Plan Last Update | C28: 46159
A30: Safety Plan submission | C30: 46161 | D30: =C30-C14 -> 13
A31: Safety Plan approval | C31: 46161
A32: Safety Plan Last Update | C32: 46161
A34: Risk Management Plan submission | D34: =C34-C14 -> -46148
A35: Risk Management Plan approval
A36: Risk Management Plan Last Update
A38: Baseline Schedule submission | C38: 46162 | D38: =C38-C14 -> 14
A39: Baseline Schedule approval | C39: 46162
A40: No of Schedule Versions | C40: 46162
A41: Last Recovery Schedule Approval Date | C41: 46162
A43: BOQ submission | C43: 46148 | D43: =C43-C19 -> -152
A44: BOQ approval | C44: 46148
A45: No of Approved Version of BOQ | C45: 46148
A47: Construction Plan submission | C47: 46162 | D47: =C47-C14 -> 14
...

Sheet Weekly Progress Report
A1: MODON - Weekly Progress Report - Construction Projects | AE1: Data Date | AF1: ='General Information'!L1 -> 46286
A2: Contract General Information | G2: Key Dates | L2: Cost Summary (SR) | T2: Performance Summary | Z2: Project Scope
A3: Project Name | B3: ='General Information'!C3 -> Improvement of Waad Al Shamal Industrial City Fence & Gates | G3: Contract Award | H3: Contract Award (Hijri) | I3: ='General Information'!C16 -> 46107 | J3: Revised Completion | K3: ='General Information'!C20 -> 46300 | L3: Original Contract Value | N3: ='Invoice Log'!E3 -> 15898659 | P3: O&M Value (if any) | R3: ='Invoice Log'!I3 -> 0 | S3: EAC | T3: Plan Value | U3: =J24 -> 0.76499456 | V3: Phys. Plan Value | W3: =T24 -> 0.63904558 | X3: Quality Score | Y3: =Quality!AC10 -> 0.86206897 | Z3: =+Progress!#REF! -> #REF!
A4: Project ID | B4: ='General Information'!C4 -> WAS1-05-006 | D4: Stage | E4: ='General Information'!C7 -> Construction | G4: Contract Sign | H4: Contract Sign (Hijri) | I4: ='General Information'!C17 -> 46107 | J4: Committed Completion | K4: ='General Information'!C21 -> 46300 | L4: Revised Contract Value | N4: ='Invoice Log'!E4 -> 15898659 | O4: EAC | P4: Submitted Invoices (Gross Value) | R4: 0 | T4: Earn Value | U4: =L24 -> 0.39339486 | V4: Phys. Earn Value | W4: =V24 -> 0.20345145 | Y4: =REPT("¢",IF(INT(+Y3*10)>5,5,INT(+Y3*10)))&REPT("£",IF(INT(+Y3*10)>5,0,5-INT(+Y3*10)))&CHAR(10)&REPT("¢",+IF(INT(+Y3*10)>5,-5+INT(+Y3*10),0))&REPT("£",IF(INT(+Y3*10)>5,10-INT(+Y3*10),5)) -> ¢¢¢¢¢ ¢¢¢££
A5: Contractor | B5: ='General Information'!C5 -> Hamza Mohammad Alderi Construction Co. | D5: Status | E5: ='General Information'!C8 -> Active | G5: Site Handover | H5: Site Handover (Hijri) | I5: ='General Information'!C18 -> 46148 | J5: Forecast Completion | K5: ='General Information'!C22 -> 46300 | L5: Estimate At Completion Value | N5: ='Invoice Log'!E5 -> 15898659 | O5: =+#REF!+#REF!+N5 -> #REF! | P5: Penalities | R5: 0 | T5: Variance | U5: =U4-U3 -> -0.3715997 | V5: Variance | W5: =W4-W3 -> -0.43559413 | X5: Safety Score | Y5: ='HSE-Stat'!J23 -> 0.85
A6: Consultant | B6: ='General Information'!C6 -> Consolidated Consultants Group | D6: Modon PM | E6: ='General Information'!C9 -> Muhammed H. Al-Essa | G6: Original Completion | H6: Original Completion (Hijri) | I6: ='General Information'!C19 -> 46300 | J6: Variance | K6: ='General Information'!C23 -> 0 | L6: Potential Changes | N6: =N4-N5 -> 0 | P6: FIR Value (Todate) | R6: 0 | T6: FIR % | U6: 0 | V6: Invoiced % | W6: 0 | Y6: =REPT("¢",IF(INT(+Y5*10)>5,5,INT(+Y5*10)))&REPT("£",IF(INT(+Y5*10)>5,0,5-INT(+Y5*10)))&CHAR(10)&REPT("¢",+IF(INT(+Y5*10)>5,-5+INT(+Y5*10),0))&REPT("£",IF(INT(+Y5*10)>5,10-INT(+Y5*10),5)) -> ¢¢¢¢¢ ¢¢¢££ | AI6: A
A8: Progress Overview
A9: Earned Value Progress (SAR) | N9: Physical Progress (Effort) | Z9: Earned Value Progress (%)
A10: WBS | C10: BOQ Value (SAR) | D10: % Wt. | E10: Weekly (SAR) | J10: To Date (SAR) | N10: Budgeted | O10: % Wt. | P10: Weekly Physical Progress | T10: To Date Physical Progress
E11: Planned | G11: Earned | I11: Original Plan % | J11: Planned | L11: Earned | N11: (Manhours) | P11: Planned | R11: Earned | T11: Planned | V11: Earned
A12: =Progress!A7 -> WAS1-05-006 - B1 - B1 - B1 - B1.2 Mobilization | C12: =Progress!B7 -> 0 | D12: =Progress!C7 -> 0 | E12: =Progress!D7 -> 0 | G12: =Progress!E7 -> 0 | I12: =Progress!F7 -> 0 | J12: =Progress!G7 -> 0 | L12: =Progress!H7 -> 0 | N12: =Progress!J7 -> 2956 | O12: =Progress!K7 -> 0.029936906 | P12: =Progress!L7 -> 0 | R12: =Progress!M7 -> 0 | T12: =Progress!N7 -> 2956 | V12: =Progress!O7 -> 2956
A13: =Progress!A8 -> WAS1-05-006 - B1 - B1 - B1 - B1.3 Preliminary Submittals | C13: =Progress!B8 -> 0 | D13: =Progress!C8 -> 0 | E13: =Progress!D8 -> 0 | G13: =Progress!E8 -> 0 | I13: =Progress!F8 -> 0 | J13: =Progress!G8 -> 0 | L13: =Progress!H8 -> 0 | N13: =Progress!J8 -> 0 | O13: =Progress!K8 -> 0 | P13: =Progress!L8 -> 0 | R13: =Progress!M8 -> 0 | T13: =Progress!N8 -> 0 | V13: =Progress!O8 -> 0
A14: =Progress!A9 -> WAS1-05-006 - B1 - B1 - B1 - B1.6 Engineering | C14: =Progress!B9 -> 476989.77 | D14: =Progress!C9 -> 0.030001887 | E14: =Progress!D9 -> 8112.07 | G14: =Progress!E9 -> 973.44 | I14: =Progress!F9 -> 473744.95 | J14: =Progress!G9 -> 473744.95 | L14: =Progress!H9 -> 181061.42 | N14: =Progress!J9 -> 4927 | O14: =Progress!K9 -> 0.049898219 | P14: =Progress!L9 -> 62 | R14: =Progress!M9 -> 154 | T14: =Progress!N9 -> 4911 | V14: =Progress!O9 -> 2854
A15: =Progress!A10 -> WAS1-05-006 - B1 - B1 - B1 - B1.7 Procurement | C15: =Progress!B10 -> 3179931.7 | D15: =Progress!C10 -> 0.20001257 | E15: =Progress!D10 -> 168485.46 | G15: =Progress!E10 -> 0 | I15: =Progress!F10 -> 3045396.1 | J15: =Progress!G10 -> 3045396.1 | L15: =Progress!H10 -> 1896470.1 | N15: =Progress!J10 -> 12811 | O15: =Progress!K10 -> 0.12974347 | P15: =Progress!L10 -> 3846 | R15: =Progress!M10 -> 0 | T15: =Progress!N10 -> 9740 | V15: =Progress!O10 -> 2301
A16: =Progress!A11 -> WAS1-05-006 - B1 - B1 - B1 - B1.8 Construction | C16: =Progress!B11 -> 10651772 | D16: =Progress!C11 -> 0.66997925 | E16: =Progress!D11 -> 1776303 | G16: =Progress!E11 -> 1557929 | I16: =Progress!F11 -> 8643246.6 | J16: =Progress!G11 -> 8643246.6 | L16: =Progress!H11 -> 4176919.2 | N16: =Progress!J11 -> 73908 | O16: =Progress!K11 -> 0.74850366 | P16: =Progress!L11 -> 8524 | R16: =Progress!M11 -> 2219 | T16: =Progress!N11 -> 45493 | V16: =Progress!O11 -> 11978
A17: =Progress!A12 -> WAS1-05-006 - B1 - B1 - B1 - B1.8.1 FENCES | C17: =Progress!B12 -> 9040220 | D17: =Progress!C12 -> 0.56861525 | E17: =Progress!D12 -> 1676971.3 | G17: =Progress!E12 -> 1536539.6 | I17: =Progress!F12 -> 7906683.8 | J17: =Progress!G12 -> 7906683.8 | L17: =Progress!H12 -> 4096091.3 | N17: =Progress!J12 -> 4885 | O17: =Progress!K12 -> 0.049472863 | P17: =Progress!L12 -> 750 | R17: =Progress!M12 -> 484 | T17: =Progress!N12 -> 4227 | V17: =Progress!O12 -> 2183
A18: =Progress!A13 -> WAS1-05-006 - B1 - B1 - B1 - B1.8.2 GUARD HOUSE 1 | C18: =Progress!B13 -> 438683.2 | D18: =Progress!C13 -> 0.027592465 | E18: =Progress!D13 -> 17202.44 | G18: =Progress!E13 -> 8065.64 | I18: =Progress!F13 -> 153069.53 | J18: =Progress!G13 -> 153069.53 | L18: =Progress!H13 -> 35100.37 | N18: =Progress!J13 -> 22300 | O18: =Progress!K13 -> 0.22584337 | P18: =Progress!L13 -> 2530 | R18: =Progress!M13 -> 483 | T18: =Progress!N13 -> 11323 | V18: =Progress!O13 -> 3732
A19: =Progress!A14 -> WAS1-05-006 - B1 - B1 - B1 - B1.8.3 GUARD HOUSE 2 | C19: =Progress!B14 -> 438683.2 | D19: =Progress!C14 -> 0.027592465 | E19: =Progress!D14 -> 15771.65 | G19: =Progress!E14 -> 5479.23 | I19: =Progress!F14 -> 197325.23 | J19: =Progress!G14 -> 197325.23 | L19: =Progress!H14 -> 10848.26 | N19: =Progress!J14 -> 22300 | O19: =Progress!K14 -> 0.22584337 | P19: =Progress!L14 -> 2410 | R19: =Progress!M14 -> 775 | T19: =Progress!N14 -> 14176 | V19: =Progress!O14 -> 2336
A20: =Progress!A15 -> WAS1-05-006 - B1 - B1 - B1 - B1.8.5 GUARD HOUSE 3 | C20: =Progress!B15 -> 438683.2 | D20: =Progress!C15 -> 0.027592465 | E20: =Progress!D15 -> 15771.65 | G20: =Progress!E15 -> 7844.51 | I20: =Progress!F15 -> 197325.23 | J20: =Progress!G15 -> 197325.23 | L20: =Progress!H15 -> 34879.24 | N20: =Progress!J15 -> 22300 | O20: =Progress!K15 -> 0.22584337 | P20: =Progress!L15 -> 2410 | R20: =Progress!M15 -> 478 | T20: =Progress!N15 -> 14176 | V20: =Progress!O15 -> 3727
A21: =Progress!A16 -> WAS1-05-006 - B1 - B1 - B1 - B1.8.4 EXT. WORKS | C21: =Progress!B16 -> 295502.16 | D21: =Progress!C16 -> 0.018586609 | E21: =Progress!D16 -> 50585.98 | G21: =Progress!E16 -> 0 | I21: =Progress!F16 -> 188842.83 | J21: =Progress!G16 -> 188842.83 | L21: =Progress!H16 -> 0 | N21: =Progress!J16 -> 2320 | O21: =Progress!K16 -> 0.023495812 | P21: =Progress!L16 -> 422 | R21: =Progress!M16 -> 0 | T21: =Progress!N16 -> 1590 | V21: =Progress!O16 -> 0
A22: =Progress!A17 -> WAS1-05-006 - B1 - B1 - B1 - B1.4 Testing & Commissioning | C22: =Progress!B17 -> 1589965.9 | D22: =Progress!C17 -> 0.10000629 | E22: =Progress!D17 -> 0 | G22: =Progress!E17 -> 0 | I22: =Progress!F17 -> 0 | J22: =Progress!G17 -> 0 | L22: =Progress!H17 -> 0 | N22: =Progress!J17 -> 3942 | O22: =Progress!K17 -> 0.039922626 | P22: =Progress!L17 -> 0 | R22: =Progress!M17 -> 0 | T22: =Progress!N17 -> 0 | V22: =Progress!O17 -> 0
A23: Total (SAR) | C23: =SUM(C12:C15,C17:C22) -> 15898659 | D23: =Progress!C18 -> 1 | E23: =Progress!D18 -> 1952900.5 | G23: =Progress!E18 -> 1558902.5 | I23: =Progress!F18 -> 12162388 | J23: =Progress!G18 -> 12162388 | L23: =Progress!H18 -> 6254450.7 | N23: =Progress!J18 -> 98741 | O23: =Progress!K18 -> 1 | P23: =Progress!L18 -> 12432 | R23: =Progress!M18 -> 2373 | T23: =Progress!N18 -> 63100 | V23: =Progress!O18 -> 20089
A24: Total (%) | E24: =E23/$C$23 -> 0.12283429 | G24: =G23/$C$23 -> 0.098052449 | J24: =J23/$C$23 -> 0.76499456 | L24: =L23/$C$23 -> 0.39339486 | P24: =P23/$N$23 -> 0.12590515 | R24: =R23/$N$23 -> 0.02403257 | T24: =T23/$N$23 -> 0.63904558 | V24: =V23/$N$23 -> 0.20345145
Z25: Construction Milestones
Z26: Item No. | AA26: Milestones | AC26: Original (Baseline) | AD26: Latest Plan | AE26: Forecast | AF26: Status | AG26: Days Change
Z27: =+Milestones!A4 -> 1 | AA27: =+Milestones!B4 -> Award Date | AC27: =+Milestones!C4 -> 46107 | AD27: =+Milestones!D4 -> 46107 | AE27: =+Milestones!E4 -> 46107 | AF27: =+Milestones!F4 -> 0 | AG27: =+Milestones!G4 -> 0
Z28: =+Milestones!A5 -> 2 | AA28: =+Milestones!B5 -> Contract Sign Date | AC28: =+Milestones!C5 -> 46107 | AD28: =+Milestones!D5 -> 46107 | AE28: =+Milestones!E5 -> 46107 | AF28: =+Milestones!F5 -> A | AG28: =+Milestones!G5 -> 0
Z29: =+Milestones!A6 -> 3 | AA29: =+Milestones!B6 -> Site Handover Date | AC29: =+Milestones!C6 -> 46148 | AD29: =+Milestones!D6 -> 46148 | AE29: =+Milestones!E6 -> 46148 | AF29: =+Milestones!F6 -> A | AG29: =+Milestones!G6 -> 0
Z30: =+Milestones!A7 -> 4 | AA30: =+Milestones!B7 -> Start Mobilization | AC30: =+Milestones!C7 -> 46148 | AD30: =+Milestones!D7 -> 46148 | AE30: =+Milestones!E7 -> 46148 | AF30: =+Milestones!F7 -> A | AG30: =+Milestones!G7 -> 0
Z31: =+Milestones!A10 -> 7 | AA31: =+Milestones!B10 -> Complete Procurement | AC31: =+Milestones!C10 -> 46293 | AD31: =+Milestones!D10 -> 46293 | AE31: =+Milestones!E10 -> 46293 | AF31: =+Milestones!F10 -> F | AG31: =+Milestones!G10 -> 0
Z32: =+Milestones!A11 -> 8 | AA32: =+Milestones!B11 -> Complete Construction Works | AC32: =+Milestones!C11 -> 46300 | AD32: =+Milestones!D11 -> 46300 | AE32: =+Milestones!E11 -> 46300 | AF32: =+Milestones!F11 -> F | AG32: =+Milestones!G11 -> 0
Z33: =+Milestones!#REF! -> #REF! | AA33: =+Milestones!#REF! -> #REF! | AC33: =+Milestones!#REF! -> #REF! | AD33: =+Milestones!#REF! -> #REF! | AE33: =+Milestones!#REF! -> #REF! | AF33: =+Milestones!#REF! -> #REF! | AG33: =+Milestones!#REF! -> #REF!
Z34: =+Milestones!A12 -> 10 | AA34: =+Milestones!B12 -> Complete Demobilization | AC34: =+Milestones!C12 -> 46300 | AD34: =+Milestones!D12 -> 46300 | AE34: =+Milestones!E12 -> 46300 | AF34: =+Milestones!F12 -> F | AG34: =+Milestones!G12 -> 0
Z35: =+Milestones!A13 -> 11 | AA35: =+Milestones!B13 -> Complete all Works including Testing & Commissioning, Cleanup, Closeout Documentation and Ready for Initial Handover | AC35: =+Milestones!C13 -> 46300 | AD35: =+Milestones!D13 -> 46300 | AE35: =+Milestones!E13 -> 46300 | AF35: =+Milestones!F13 -> F | AG35: =+Milestones!G13 -> 0
Z36: =+Milestones!A14 -> 12 | AA36: =+Milestones!B14 -> Project Completion Date | AC36: =+Milestones!C14 -> 46300 | AD36: =+Milestones!D14 -> 46300 | AE36: =+Milestones!E14 -> 46300 | AF36: =+Milestones!F14 -> F | AG36: =+Milestones!G14 -> 0
A52: Performance overview
A53: Submittals Status | K53: Quality | V53: Safety
A54: Shop Drawings | K54: Quality Reports | V54: Safety Statistics | AD54: Proactive Vs Reactive Actions Taken
A55: Item Per WBS | C55: Total | D55: Total Submitted Drawings | H55: Remaining | I55: Pending | J55: Total Submittals | K55: Quality Reports | M55: Issued | N55: Closed | O55: Pending | P55: Avg. Closing (Days) | Q55: Pending | V55: Category | W55: Item | Y55: This Week | AA55: This Month | AB55: Year to Date | AC55: Cumulative
D56: A | E56: B | F56: C | G56: D | Q56: 0-10 Days | R56: 11-20 Days | S56: 21-30 Days | T56: 31-60 Days | U56: > 60 Days
...

Sheet Sheet1
B2: Planned (%) | C2: Earned (%)
A3: KUMT-05-001.6 Engineering | B3: =Progress!G8 -> 0 | C3: =Progress!H8 -> 0
A4: KUMT-05-001.7 Procurement | B4: =Progress!G10 -> 3045396.1 | C4: =Progress!H10 -> 1896470.1
A5: KUMT-05-001.3 Construction | B5: =Progress!G11 -> 8643246.6 | C5: =Progress!H11 -> 4176919.2

Sheet Progress
A1: Project Scope Statement | R1: ='General Information'!$K$1 -> Data Date | S1: ='General Information'!L1 -> 46286
A4: Earned Value Progress (SAR) | J4: Physical Progress (Effort) | Q4: Previous week EV | T4: Previous week Effort
A5: WBS | B5: BOQ Value (SAR) | C5: % Wt. | D5: Weekly (SAR) | G5: To Date (SAR) | J5: Budgeted | K5: % Wt. | L5: Weekly Physical Progress | N5: To Date Physical Progress
D6: Planned | E6: Earned | F6: Original Plan | G6: Planned | H6: Earned | J6: (Manhours) | L6: Planned | M6: Earned | N6: Planned | O6: Earned | Q6: Planned | R6: Earned | T6: Planned | U6: Earned
A7: WAS1-05-006 - B1 - B1 - B1 - B1.2 Mobilization | B7: 0 | C7: =IF(ISBLANK(B7),"",B7/$B$18) -> 0 | D7: =G7-Q7 -> 0 | E7: =H7-R7 -> 0 | F7: 0 | G7: 0 | H7: 0 | J7: 2956 | K7: =J7/$J$18 -> 0.029936906 | L7: =N7-T7 -> 0 | M7: =O7-U7 -> 0 | N7: 2956 | O7: 2956 | Q7: 0 | R7: 0 | T7: 2956 | U7: 2956
A8: WAS1-05-006 - B1 - B1 - B1 - B1.3 Preliminary Submittals | B8: 0 | C8: =IF(ISBLANK(B8),"",B8/$B$18) -> 0 | D8: =G8-Q8 -> 0 | E8: =H8-R8 -> 0 | F8: 0 | G8: 0 | H8: 0 | J8: 0 | K8: =J8/$J$18 -> 0 | L8: =N8-T8 -> 0 | M8: =O8-U8 -> 0 | N8: 0 | O8: 0 | Q8: 0 | R8: 0 | T8: 0 | U8: 0
A9: WAS1-05-006 - B1 - B1 - B1 - B1.6 Engineering | B9: 476989.77 | C9: =IF(ISBLANK(B9),"",B9/$B$18) -> 0.030001887 | D9: =G9-Q9 -> 8112.07 | E9: =H9-R9 -> 973.44 | F9: 473744.95 | G9: 473744.95 | H9: 181061.42 | J9: 4927 | K9: =J9/$J$18 -> 0.049898219 | L9: =N9-T9 -> 62 | M9: =O9-U9 -> 154 | N9: 4911 | O9: 2854 | Q9: 465632.88 | R9: 180087.98 | T9: 4849 | U9: 2700
A10: WAS1-05-006 - B1 - B1 - B1 - B1.7 Procurement | B10: 3179931.7 | C10: =IF(ISBLANK(B10),"",B10/$B$18) -> 0.20001257 | D10: =G10-Q10 -> 168485.46 | E10: =H10-R10 -> 0 | F10: 3045396.1 | G10: 3045396.1 | H10: 1896470.1 | J10: 12811 | K10: =J10/$J$18 -> 0.12974347 | L10: =N10-T10 -> 3846 | M10: =O10-U10 -> 0 | N10: 9740 | O10: 2301 | Q10: 2876910.7 | R10: 1896470.1 | T10: 5894 | U10: 2301
A11: WAS1-05-006 - B1 - B1 - B1 - B1.8 Construction | B11: 10651772 | C11: =IF(ISBLANK(B11),"",B11/$B$18) -> 0.66997925 | D11: =G11-Q11 -> 1776303 | E11: =H11-R11 -> 1557929 | F11: 8643246.6 | G11: 8643246.6 | H11: 4176919.2 | J11: 73908 | K11: =J11/$J$18 -> 0.74850366 | L11: =N11-T11 -> 8524 | M11: =O11-U11 -> 2219 | N11: 45493 | O11: 11978 | Q11: 6866943.6 | R11: 2618990.1 | T11: 36969 | U11: 9759
A12: WAS1-05-006 - B1 - B1 - B1 - B1.8.1 FENCES | B12: 9040220 | C12: =IF(ISBLANK(B12),"",B12/$B$18) -> 0.56861525 | D12: =F12-Q12 -> 1676971.3 | E12: =H12-R12 -> 1536539.6 | F12: 7906683.8 | G12: 7906683.8 | H12: 4096091.3 | J12: 4885 | K12: =J12/$J$18 -> 0.049472863 | L12: =N12-T12 -> 750 | M12: =O12-U12 -> 484 | N12: 4227 | O12: 2183 | Q12: 6229712.5 | R12: 2559551.7 | T12: 3477 | U12: 1699
A13: WAS1-05-006 - B1 - B1 - B1 - B1.8.2 GUARD HOUSE 1 | B13: 438683.2 | C13: =IF(ISBLANK(B13),"",B13/$B$18) -> 0.027592465 | D13: =F13-Q13 -> 17202.44 | E13: =H13-R13 -> 8065.64 | F13: 153069.53 | G13: 153069.53 | H13: 35100.37 | J13: 22300 | K13: =J13/$J$18 -> 0.22584337 | L13: =N13-T13 -> 2530 | M13: =O13-U13 -> 483 | N13: 11323 | O13: 3732 | Q13: 135867.09 | R13: 27034.73 | T13: 8793 | U13: 3249
A14: WAS1-05-006 - B1 - B1 - B1 - B1.8.3 GUARD HOUSE 2 | B14: 438683.2 | C14: =IF(ISBLANK(B14),"",B14/$B$18) -> 0.027592465 | D14: =F14-Q14 -> 15771.65 | E14: =H14-R14 -> 5479.23 | F14: 197325.23 | G14: 197325.23 | H14: 10848.26 | J14: 22300 | K14: =J14/$J$18 -> 0.22584337 | L14: =N14-T14 -> 2410 | M14: =O14-U14 -> 775 | N14: 14176 | O14: 2336 | Q14: 181553.58 | R14: 5369.03 | T14: 11766 | U14: 1561
A15: WAS1-05-006 - B1 - B1 - B1 - B1.8.5 GUARD HOUSE 3 | B15: 438683.2 | C15: =IF(ISBLANK(B15),"",B15/$B$18) -> 0.027592465 | D15: =F15-Q15 -> 15771.65 | E15: =H15-R15 -> 7844.51 | F15: 197325.23 | G15: 197325.23 | H15: 34879.24 | J15: 22300 | K15: =J15/$J$18 -> 0.22584337 | L15: =N15-T15 -> 2410 | M15: =O15-U15 -> 478 | N15: 14176 | O15: 3727 | Q15: 181553.58 | R15: 27034.73 | T15: 11766 | U15: 3249
A16: WAS1-05-006 - B1 - B1 - B1 - B1.8.4 EXT. WORKS | B16: 295502.16 | C16: =IF(ISBLANK(B16),"",B16/$B$18) -> 0.018586609 | D16: =F16-Q16 -> 50585.98 | E16: =H16-R16 -> 0 | F16: 188842.83 | G16: 188842.83 | H16: 0 | J16: 2320 | K16: =J16/$J$18 -> 0.023495812 | L16: =N16-T16 -> 422 | M16: =O16-U16 -> 0 | N16: 1590 | O16: 0 | Q16: 138256.85 | R16: 0 | T16: 1168 | U16: 0
A17: WAS1-05-006 - B1 - B1 - B1 - B1.4 Testing & Commissioning | B17: 1589965.9 | C17: =IF(ISBLANK(B17),"",B17/$B$18) -> 0.10000629 | D17: =F17-Q17 -> 0 | E17: =H17-R17 -> 0 | F17: 0 | G17: 0 | H17: 0 | J17: 3942 | K17: =J17/$J$18 -> 0.039922626 | L17: =N17-T17 -> 0 | M17: =O17-U17 -> 0 | N17: 0 | O17: 0 | Q17: 0 | R17: 0 | T17: 0 | U17: 0
B18: =SUM(B9:B10,B12:B17) -> 15898659 | C18: =SUM(C7:C10,C12:C17) -> 1 | D18: =SUM(D7:D11) -> 1952900.5 | E18: =SUM(E7:E11) -> 1558902.5 | F18: =SUM(F7:F11) -> 12162388 | G18: =SUM(G7:G11) -> 12162388 | H18: =SUM(H7:H11) -> 6254450.7 | J18: =SUM(J7:J10,J12:J17) -> 98741 | K18: =SUM(K7:K10,K12:K17) -> 1 | L18: =SUM(L7:L11) -> 12432 | M18: =SUM(M7:M11) -> 2373 | N18: =SUM(N7:N11) -> 63100 | O18: =SUM(O7:O11) -> 20089 | Q18: 10209487 | R18: 4695548.2 | T18: 50668 | U18: 17716
D19: =D18/$B$18 -> 0.12283429 | E19: =E18/$B$18 -> 0.098052449 | F19: =F18/$B$18 -> 0.76499456 | G19: =G18/$B$18 -> 0.76499456 | H19: =H18/$B$18 -> 0.39339486 | L19: =L18/$J$18 -> 0.12590515 | M19: =M18/$J$18 -> 0.02403257 | N19: =N18/$J$18 -> 0.63904558 | O19: =O18/$J$18 -> 0.20345145 | Q19: 0.64216026 | R19: 0.29534241 | T19: 0.51416104 | U19: 0.17977574
H21: =H19-G19 -> -0.3715997
O24: =O19-N19 -> -0.43559413

Sheet Weekly Photos
B1: Date | C1: ='Weekly Progress Report'!AF1 -> 46286
B4: S.O.G Works | L4: Fence Works
B23: Fence Works | L23: Fence Works

Sheet FIR Summary
A2: Project Name | C2: ='General Information'!C3 -> Improvement of Waad Al Shamal Industrial City Fence & Gates | I2: Total FIR Amount
A3: Project ID | C3: ='General Information'!C4 -> WAS1-05-006 | E3: Project Budget | F3: =Progress!B18 -> 15898659 | I3: 0
A4: Date Pariod | C4: Start Date | D4: =G4-6 -> 46280 | E4: To | F4: Data Date | G4: ='General Information'!L1 -> 46286 | I4: =Total -> 0
A6: BOQ Item # | B6: BOQ Description | C6: FIR # | D6: Date | E6: FIR Description | F6: Unit Rate | G6: Current Pariod Quantity | H6: Total (SR) | I6: Comments
H7: =F7*G7 -> 0
H8: =F8*G8 -> 0
A9: BILL NO.1 B1.02 00 00 | B9: BILL NO.3 STRUCTURAL WORKS | H9: =Total -> 0

Sheet Quality
B2: QC OBSERVATIONS CHECKLIST
BB4: ='General Information'!C14 -> 46148
B6: Project No. | E6: ='[47]General Information'!C4 -> WAS1-05-006 | K6: OBS No. | O6: 12 | U6: Inspection Day: | X6: 46284
B8: Project | E8: ='[47]General Information'!C3 -> Improvement of Waad Al Shamal Industrial City Fence & Gates | O8: Contractor: Consultant: | U8: ='[47]General Information'!C5&" "&'[47]General Information'!C6 -> Hamza Mohammad Alderi Construction Co. Consolidated Consultants Group
B10: 4 | D10: Excellent | G10: Quality Management System is being practiced and applies to MODON System | Z10: 90 - 100 | AB10: QC Overall Score | AC10: =Q49 -> 0.86206897 | AN10: =SUM(Z10:Z13) -> 0 | AO10: 100 | AP10: 0.22883295
B11: 3 | D11: Good | G11: Evidence of compliance with plans and procedures. | Z11: 80 - 89 | AN11: =SUM(Y10:Y14) -> 0 | AO11: 89 | AP11: 0.20366133
B12: 2 | D12: Average | G12: Indication level of compliance with standards but there is room for improvement | Z12: 70 - 79 | AO12: 79 | AP12: 0.18077803
B13: 1 | D13: Improve | G13: Quality and Control is NOT being managed effectively. Needs Improvement | Z13: ≤ 69 | AO13: 69 | AP13: 0.15789474
B14: 0 | D14: N/A | G14: Item was not applicable or this item was not reviewed during the inspection. | Z14: Zero | AO14: 100 | AP14: 0.22883295
B16: No. | C16: Topic | K16: E (4) | L16: G (3) | M16: A (2) | N16: I (1) | O16: N/A (0) | Q16: No. | R16: Topic | Z16: E (4) | AA16: G (3) | AB16: A (2) | AC16: I (1) | AD16: N/A (0) | AO16: =SUM(AO10:AO15) -> 437
K17: 1 | L17: 0.89 | M17: 0.79 | N17: 0.69 | O17: 1 | Z17: 1 | AA17: 0.89 | AB17: 0.79 | AC17: 0.69 | AD17: 1 | AF17: =SUM(AF18:AG46)/COUNT(AF18:AG46) -> 0.86206897
B18: 1 | C18: Control of Access to Site/Office | K18: 0 | L18: 1 | Q18: 30 | R18: QC of Excavation | Z18: 0 | AA18: 1 | AD18: 0 | AF18: =SUMPRODUCT($K$17:$O$17,K18:O18) -> 0.89 | AG18: =SUMPRODUCT($Z$17:$AD$17,Z18:AD18) -> 0.89 | AV18: Item Count | AW18: Score | AX18: Distributtion
B19: 2 | C19: Document Control Administration | K19: 0 | L19: 1 | M19: 0 | Q19: 31 | R19: QC of Roads/Round about | AA19: 0 | AD19: 1 | AF19: =SUMPRODUCT($K$17:$O$17,K19:O19) -> 0.89 | AG19: =SUMPRODUCT($Z$17:$AD$17,Z19:AD19) -> 1 | AX19: Overall | AY19: Relevant
B20: 3 | C20: Project Documents and Progress | L20: 1 | Q20: 32 | R20: QC of Interlock & Curbstone | Z20: 0 | AA20: 1 | AF20: =SUMPRODUCT($K$17:$O$17,K20:O20) -> 0.89 | AG20: =SUMPRODUCT($Z$17:$AD$17,Z20:AD20) -> 0.89 | AM20: 4 | AN20: =58 -> 58 | AO20: counts | AQ20: 4 | AR20: Excellent | AV20: =SUM(Z18:Z46,K18:K46) -> 2 | AW20: =AQ20*AV20 -> 8 | AX20: =AV20/$AV$25 -> 0.034482759 | AY20: =AV20/SUM($AV$20:$AV$23) -> 0.047619048
B21: 4 | C21: Contractor's Quality Plan/CM (Updated and Reviewed) | K21: 1 | M21: 0 | Q21: 33 | R21: Layers/Backfilling Sampling | Z21: 0 | AA21: 1 | AD21: 0 | AF21: =SUMPRODUCT($K$17:$O$17,K21:O21) -> 1 | AG21: =SUMPRODUCT($Z$17:$AD$17,Z21:AD21) -> 0.89 | AM21: 3 | AN21: =58 -> 58 | AO21: counts | AQ21: 3 | AR21: Good | AV21: =SUM(L18:L46,AA18:AA46) -> 14 | AW21: =AQ21*AV21 -> 42 | AX21: =AV21/$AV$25 -> 0.24137931 | AY21: =AV21/SUM($AV$20:$AV$23) -> 0.33333333
B22: 5 | C22: MS Log and Paperwork | K22: 0 | L22: 0 | M22: 1 | Q22: 34 | R22: Pump Stations Units | Z22: 0 | AA22: 0 | AB22: 0 | AD22: 1 | AF22: =SUMPRODUCT($K$17:$O$17,K22:O22) -> 0.79 | AG22: =SUMPRODUCT($Z$17:$AD$17,Z22:AD22) -> 1 | AM22: 2 | AN22: =58 -> 58 | AO22: counts | AQ22: 2 | AR22: Average | AV22: =SUM(M18:M46,AB18:AB46) -> 16 | AW22: =AQ22*AV22 -> 32 | AX22: =AV22/$AV$25 -> 0.27586207 | AY22: =AV22/SUM($AV$20:$AV$23) -> 0.38095238 | BC22: NB: Insert 1, or 0 in the required cell only.
B23: 6 | C23: RFI, FIR, & MIR Procedure | K23: 0 | L23: 1 | Q23: 35 | R23: Quality of Form Work | Z23: 1 | AA23: 0 | AD23: 0 | AF23: =SUMPRODUCT($K$17:$O$17,K23:O23) -> 0.89 | AG23: =SUMPRODUCT($Z$17:$AD$17,Z23:AD23) -> 1 | AM23: 1 | AN23: =58 -> 58 | AO23: counts | AQ23: 1 | AR23: Improve | AV23: =SUM(N18:N46,AC18:AC46) -> 10 | AW23: =AQ23*AV23 -> 10 | AX23: =AV23/$AV$25 -> 0.17241379 | AY23: =AV23/SUM($AV$20:$AV$23) -> 0.23809524
B24: 7 | C24: RFI, FIR, & MIR Inventory system | K24: 0 | L24: 1 | Q24: 36 | R24: Design Change List | AC24: 0 | AD24: 1 | AF24: =SUMPRODUCT($K$17:$O$17,K24:O24) -> 0.89 | AG24: =SUMPRODUCT($Z$17:$AD$17,Z24:AD24) -> 1 | AM24: 0 | AN24: =58 -> 58 | AO24: counts | AQ24: 0 | AR24: N/A | AV24: =SUM(O18:O46,AD18:AD46) -> 16 | AW24: =AQ24*AV24 -> 0 | AX24: =AV24/$AV$25 -> 0.27586207 | AY24: -
B25: 8 | C25: NCRs Control & Procedure | K25: 0 | L25: 0 | M25: 1 | O25: 0 | Q25: 37 | R25: Quality of Concrete Placing | Z25: 0 | AA25: 0 | AB25: 1 | AF25: =SUMPRODUCT($K$17:$O$17,K25:O25) -> 0.79 | AG25: =SUMPRODUCT($Z$17:$AD$17,Z25:AD25) -> 0.79 | AR25: Total | AV25: =SUM(AV20:AV24) -> 58 | AW25: =SUM(AW20:AW24) -> 92 | AX25: =SUM(AX20:AX24) -> 1 | AY25: =SUM(AY20:AY24) -> 1
B26: 9 | C26: NCR Log | K26: 0 | M26: 1 | O26: 0 | Q26: 38 | R26: Concrete Surface Finishing | Z26: 0 | AA26: 0 | AB26: 1 | AF26: =SUMPRODUCT($K$17:$O$17,K26:O26) -> 0.79 | AG26: =SUMPRODUCT($Z$17:$AD$17,Z26:AD26) -> 0.79
B27: 10 | C27: MODON Standard* | K27: 0 | L27: 1 | Q27: 39 | R27: Pedestals/Columns/Beams Alignment | Z27: 0 | AA27: 0 | AB27: 1 | AF27: =SUMPRODUCT($K$17:$O$17,K27:O27) -> 0.89 | AG27: =SUMPRODUCT($Z$17:$AD$17,Z27:AD27) -> 0.79 | AV27: Maz Score Available: | AW27: =SUM(AV20:AV23)*AQ20 -> 168 | AX27: <- Excludes N/A items
B28: 11 | C28: Project Risk Plan/Management* | K28: 0 | L28: 0 | M28: 1 | Q28: 40 | R28: Siporex Lifting & Unloading | AA28: 0 | AB28: 0 | AD28: 1 | AF28: =SUMPRODUCT($K$17:$O$17,K28:O28) -> 0.79 | AG28: =SUMPRODUCT($Z$17:$AD$17,Z28:AD28) -> 1
B29: 12 | C29: Monthly Quality Reports* | K29: 0 | L29: 0 | M29: 1 | Q29: 41 | R29: Siporex Quality Pre-installation | AA29: 0 | AD29: 1 | AF29: =SUMPRODUCT($K$17:$O$17,K29:O29) -> 0.79 | AG29: =SUMPRODUCT($Z$17:$AD$17,Z29:AD29) -> 1
B30: 13 | C30: ITP | K30: 0 | L30: 1 | Q30: 42 | R30: Siporex Finishing Quality | Z30: 0 | AA30: 0 | AD30: 1 | AF30: =SUMPRODUCT($K$17:$O$17,K30:O30) -> 0.89 | AG30: =SUMPRODUCT($Z$17:$AD$17,Z30:AD30) -> 1 | AR30: Total Score | AW30: Percentage (%)
B31: 14 | C31: MODON Weekly Report | K31: 0 | L31: 1 | Q31: 43 | R31: Roads / Parking Markings | AA31: 0 | AD31: 1 | AF31: =SUMPRODUCT($K$17:$O$17,K31:O31) -> 0.89 | AG31: =SUMPRODUCT($Z$17:$AD$17,Z31:AD31) -> 1 | AN31: =MAX(AN20:AN24) -> 58 | AR31: =AW25 -> 92 | AW31: =SUM(100/AR33*AR31) -> 54.761905 | AY31: %
B32: 15 | C32: Design Change Official Paperwork* | K32: 0 | L32: 0 | O32: 1 | Q32: 44 | R32: QC of Finishing Outdoors | Z32: 0 | AA32: 0 | AD32: 1 | AF32: =SUMPRODUCT($K$17:$O$17,K32:O32) -> 1 | AG32: =SUMPRODUCT($Z$17:$AD$17,Z32:AD32) -> 1 | AR32: Max Score Available | BP32: 31
B33: 16 | C33: Design Change was Applied* | K33: 0 | L33: 0 | O33: 1 | Q33: 45 | R33: Quality of Finishing Indoors | Z33: 0 | AA33: 0 | AD33: 1 | AF33: =SUMPRODUCT($K$17:$O$17,K33:O33) -> 1 | AG33: =SUMPRODUCT($Z$17:$AD$17,Z33:AD33) -> 1 | AR33: =AW27 -> 168 | BP33: 32
B34: 17 | C34: Material List | K34: 0 | L34: 0 | N34: 1 | Q34: 46 | R34: Stairs Quality | Z34: 0 | AB34: 0 | AD34: 1 | AF34: =SUMPRODUCT($K$17:$O$17,K34:O34) -> 0.69 | AG34: =SUMPRODUCT($Z$17:$AD$17,Z34:AD34) -> 1 | BP34: 33
B35: 18 | C35: Pending Material Status | K35: 0 | N35: 1 | O35: 0 | Q35: 47 | R35: Tanks Method Statement Work | AC35: 1 | AD35: 0 | AF35: =SUMPRODUCT($K$17:$O$17,K35:O35) -> 0.69 | AG35: =SUMPRODUCT($Z$17:$AD$17,Z35:AD35) -> 0.69 | BP35: 34
B36: 19 | C36: Lifting Plan* | M36: 0 | N36: 1 | O36: 0 | Q36: 48 | R36: Electric Rooms | Z36: 0 | AC36: 1 | AD36: 0 | AF36: =SUMPRODUCT($K$17:$O$17,K36:O36) -> 0.69 | AG36: =SUMPRODUCT($Z$17:$AD$17,Z36:AD36) -> 0.69 | BP36: 35
B37: 20 | C37: DWG Log | K37: 0 | M37: 1 | Q37: 49 | R37: QC of MCC/ATS Plant Units | Z37: 0 | AD37: 1 | AF37: =SUMPRODUCT($K$17:$O$17,K37:O37) -> 0.79 | AG37: =SUMPRODUCT($Z$17:$AD$17,Z37:AD37) -> 1 | BP37: 36
B38: 21 | C38: Invoice Status | K38: 0 | L38: 0 | M38: 1 | N38: 0 | O38: 0 | Q38: 50 | R38: Qualified Subcontractor | Z38: 0 | AA38: 1 | AD38: 0 | AF38: =SUMPRODUCT($K$17:$O$17,K38:O38) -> 0.79 | AG38: =SUMPRODUCT($Z$17:$AD$17,Z38:AD38) -> 0.89 | BP38: 37
B39: 22 | C39: Site Handover Letter | K39: 0 | L39: 0 | O39: 1 | Q39: 51 | R39: Scaffold/Ladders/Slope/Bridge Compliance | Z39: 0 | AC39: 1 | AD39: 0 | AF39: =SUMPRODUCT($K$17:$O$17,K39:O39) -> 1 | AG39: =SUMPRODUCT($Z$17:$AD$17,Z39:AD39) -> 0.69 | BP39: 38
B40: 23 | C40: Material Testing Results & Certification | K40: 0 | L40: 1 | Q40: 52 | R40: Protection Applied to Completed Work | AC40: 1 | AD40: 0 | AF40: =SUMPRODUCT($K$17:$O$17,K40:O40) -> 0.89 | AG40: =SUMPRODUCT($Z$17:$AD$17,Z40:AD40) -> 0.69
B41: 24 | C41: As Build Drawings Status* | L41: 0 | O41: 1 | Q41: 53 | R41: Storage Management in/out Control | Z41: 0 | AA41: 0 | AB41: 1 | AC41: 0 | AF41: =SUMPRODUCT($K$17:$O$17,K41:O41) -> 1 | AG41: =SUMPRODUCT($Z$17:$AD$17,Z41:AD41) -> 0.79
B42: 25 | C42: Calibrated Lab Tools & Equipment | K42: 0 | M42: 1 | Q42: 54 | R42: Material Control | Z42: 0 | AA42: 0 | AB42: 1 | AC42: 0 | AF42: =SUMPRODUCT($K$17:$O$17,K42:O42) -> 0.79 | AG42: =SUMPRODUCT($Z$17:$AD$17,Z42:AD42) -> 0.79
B43: 26 | C43: Storage Inventory System | M43: 0 | N43: 1 | Q43: 55 | R43: Manholes Storing and Quality | AA43: 0 | AD43: 1 | AF43: =SUMPRODUCT($K$17:$O$17,K43:O43) -> 0.69 | AG43: =SUMPRODUCT($Z$17:$AD$17,Z43:AD43) -> 1
B44: 27 | C44: Logistics Plan | N44: 1 | Q44: 56 | R44: Reinforced Steel Quality | Z44: 0 | AA44: 1 | AF44: =SUMPRODUCT($K$17:$O$17,K44:O44) -> 0.69 | AG44: =SUMPRODUCT($Z$17:$AD$17,Z44:AD44) -> 0.89
B45: 28 | C45: Project Progress Planview | L45: 0 | M45: 0 | N45: 1 | Q45: 57 | R45: Safety Overview | Z45: 0 | AA45: 0 | AB45: 1 | AC45: 0 | AF45: =SUMPRODUCT($K$17:$O$17,K45:O45) -> 0.69 | AG45: =SUMPRODUCT($Z$17:$AD$17,Z45:AD45) -> 0.79
B46: 29 | C46: Sufficient Number of QC Inspectors | K46: 0 | M46: 1 | N46: 0 | O46: 0 | Q46: 58 | R46: Waste Management Control | Z46: 0 | AA46: 0 | AB46: 1 | AF46: =SUMPRODUCT($K$17:$O$17,K46:O46) -> 0.79 | AG46: =SUMPRODUCT($Z$17:$AD$17,Z46:AD46) -> 0.79
...

Sheet Quality-Stat
A1: Quality Reports
A2: Item | C2: Issued | D2: Closed | E2: Pending | F2: Avg. Closing (Days) | G2: Pending
G3: 0-10 Days | H3: 11-20 Days | I3: 21-30 Days | J3: 31-60 Days | K3: > 60 Days
A5: Non Conforomance Report (NCR) | C5: 0 | D5: 0 | E5: =+C5-D5 -> 0 | F5: 0 | G5: 0 | H5: 0 | I5: 0 | J5: 0 | K5: 0
A6: Site Instruction (SI) | C6: 0 | D6: 0 | E6: 0 | F6: 0 | G6: 0 | H6: 0 | I6: 0 | J6: 0 | K6: 0
A7: Material Inspection Report (MIR) | C7: 29 | D7: 24 | E7: 5 | F7: 0 | G7: 0 | H7: 0 | I7: 0 | J7: 0 | K7: 0
A8: Field Inspection Report (FIR) | C8: 265 | D8: 229 | E8: 36 | F8: 0 | G8: 0 | H8: 0 | I8: 0 | J8: 0 | K8: 0
A10: Shop Drawings
A11: Item Per WBS | D11: Total | E11: Total Drawings Submitted | J11: Remaining Drawings | K11: Pending | L11: Total Submittals
E12: A | F12: B | G12: C | H12: D | I12: Processed | J12: with Designer | K12: Submittals With Consultant
A13: Civil | D13: 13 | E13: 5 | F13: 7 | G13: 0 | H13: 1 | I13: =SUM(E13:H13) -> 13 | J13: =D13-L13 -> 0 | K13: 0 | L13: =I13+K13 -> 13
A14: Structural | C14: Structural | E14: 0 | F14: 0 | G14: 0 | H14: 0 | I14: =SUM(E14:H14) -> 0 | J14: =D14-L14 -> 0 | L14: =I14+K14 -> 0
A15: Architectural | C15: Architectural | D15: 10 | E15: 3 | F15: 7 | G15: 0 | H15: 0 | I15: =SUM(E15:H15) -> 10 | J15: =D15-L15 -> 0 | K15: 0 | L15: =I15+K15 -> 10
A16: Mechanical | C16: Mechanical | D16: 4 | E16: 0 | F16: 4 | G16: 0 | H16: 0 | I16: =SUM(E16:H16) -> 4 | J16: =D16-L16 -> 0 | K16: 0 | L16: =I16+K16 -> 4
A17: Electrical | C17: Electrical | D17: 8 | E17: 0 | F17: 7 | G17: 0 | H17: 0 | I17: =SUM(E17:H17) -> 7 | J17: =D17-L17 -> 0 | K17: 1 | L17: =I17+K17 -> 8
A18: TOTAL | D18: =SUM(D13:D17) -> 35 | E18: =SUM(E13:E17) -> 8 | F18: =SUM(F13:F17) -> 25 | G18: =SUM(G13:G17) -> 0 | H18: =SUM(H13:H17) -> 1 | I18: =SUM(I13:I17) -> 34 | J18: =SUM(J13:J17) -> 0 | K18: =SUM(K13:K17) -> 1 | L18: =SUM(L13:L17) -> 35
A21: Material Approval
A22: Item Per WBS | D22: Total | E22: Total Materials Submitted | J22: Remaining to approve | K22: Pending | L22: Total Submittals
E23: A | F23: B | G23: C | H23: D | I23: Processed | J23: with Designer | K23: Submittals With Consultant
A24: Civil | D24: 23 | F24: 23 | I24: =SUM(E24:H24) -> 23 | J24: =D24-L24 -> 0 | K24: 0 | L24: =I24+K24 -> 23
A25: Structural | C25: Structural | I25: =SUM(E25:H25) -> 0 | J25: =D25-L25 -> 0 | L25: =I25+K25 -> 0
A26: Architectural | C26: Architectural | D26: 19 | F26: 18 | G26: 1 | I26: =SUM(E26:H26) -> 19 | J26: =D26-L26 -> 0 | K26: 0 | L26: =I26+K26 -> 19
A27: Mechanical | C27: Mechanical | D27: 27 | F27: 26 | G27: 0 | H27: 1 | I27: =SUM(E27:H27) -> 27 | J27: =D27-L27 -> 0 | K27: 0 | L27: =I27+K27 -> 27
A28: Electrical | C28: Electrical | D28: 21 | F28: 19 | G28: 1 | H28: 1 | I28: =SUM(E28:H28) -> 21 | J28: =D28-L28 -> 0 | K28: 0 | L28: =I28+K28 -> 21
A29: TOTAL | D29: =SUM(D24:D28) -> 90 | E29: =SUM(E24:E28) -> 0 | F29: =SUM(F24:F28) -> 86 | G29: =SUM(G24:G28) -> 2 | H29: =SUM(H24:H28) -> 2 | I29: =SUM(I24:I28) -> 90 | J29: =SUM(J24:J28) -> 0 | K29: =SUM(K24:K28) -> 0 | L29: =SUM(L24:L28) -> 90
A31: Procurement Summary
A32: Item Per WBS | D32: Total Materials | E32: Total Number of P.O. | F32: Actual P.O. To Date | G32: Remaining P.O | H32: Actual Material on Site | I32: Remaining Materials | J32: Material Delivery Completion (Date)
E33: A | F33: B | G33: C | H33: D | I33: Processed
A34: Civil
A35: Structural | C35: Structural
A36: Architectural | C36: Architectural
A37: Mechanical | C37: Mechanical
A38: Electrical | C38: Electrical
A39: TOTAL | D39: =SUM(D34:D38) -> 0 | E39: =SUM(E34:E38) -> 0 | F39: =SUM(F34:F38) -> 0 | G39: =SUM(G34:G38) -> 0 | H39: =SUM(H34:H38) -> 0 | I39: =SUM(I34:I38) -> 0 | J39: =MAX(J34:J38) -> 0
A41: Contractor Quality Inspections / Observations (Weekly Basis) | I41: Overall Average | J41: =AVERAGE(E43:E210) -> 0.89483333 | L41: Average Closing | M41: =AVERAGE(G43:G115) -> 1.0833333
A42: Week Number | B42: Date of Audit | C42: Date Issued | D42: Numbers Of Comments | E42: Quality Score | F42: Date Closed | G42: Closure Duration | I42: This Week Score | J42: =[48]Quality!AC10 -> 0.915 | L42: Average Number of Comments Per Audit | M42: =AVERAGE(D43:D115) -> 1.25
A43: Week-1 | B43: 46209 | C43: 46209 | D43: 2 | E43: 0.918 | F43: 46210 | G43: 1
A44: Week-2 | B44: 46216 | C44: 46216 | D44: 2 | E44: 0.91 | F44: 46218 | G44: 2
A45: Week-3 | B45: 46219 | C45: 46221 | D45: 2 | E45: 0.908 | F45: 46222 | G45: 1
A46: Week-4 | B46: 46226 | C46: 46228 | D46: 1 | E46: 0.9 | F46: 46229 | G46: 1
...

Sheet HSE
B1: MODON HSE Site Inspection Report
B2: Date | E2: 46284 | L2: Inspected By: | U2: Mr. Noaman Shah
B4: Project ID. | E4: WAS1-05-006 | L4: Report No. | P4: 12 | W4: MODON PM Name | Y4: Eng. Mohammad Eisa
B6: Project Name: | E6: Improvement of WAS Fence and Gate Project | L6: Contractor: | R6: Hamza Mohammad Alderi Contracting Co. | X6: Safety Performance | AA6: =IF(W29>0,3,IF(L29>6,2,IF(D29>0,2,1)*1)*1) -> 2 | AE6: =(((COUNTIF(L13:Q25,"1")+COUNTIF(AC13:AH25,"1"))*AR13)+(COUNTIF(L13:Q25,"2")+COUNTIF(AC13:AH25,"2"))*AR14+(COUNTIF(L13:Q25,"3")+COUNTIF(AC13:AH25,"3"))*AR15)/((COUNT(L13:Q25)+COUNT(AC13:AH25))*100) -> 0.8452381
B8: Inspections are a snapshot in time and refer only to the practices and documentation observed at the time of the Inspection. It remains the responsibility of the Consultant and Contractor to ensure that all aspects of Health & Safety are suitably managed.
B9: 1 | D9: Good Practice | H9: 2 | I9: Need Improvement | T9: 3 | U9: Fail (Life Threatening Activity) / Compliance with Plan & Procedures | X9: N/A | Y9: Atcitty Not Applicable for this Site Inspection Report
B11: No. | C11: Topic | K11: Wt. | L11: HSE Compliance | S11: No. | T11: Topic | AB11: Wt. | AC11: HSE Compliance
B13: 1 | C13: Access and Egress - (General access to site, segregated from vehicles, / Overhead protection, while entering into the building /Adequate lighting provided when dark or overnight work) | K13: 0.05 | L13: 2 | S13: 14 | T13: Work at Height - (PPE/Fall Protection(Same level, above and blow) / Training / Fall restraint / competency /Safe access & egress to and from work at height / Ladders / Openings (floor/shafts/Provision of emergency rescue) | AB13: 0.05 | AC13: 2 | AP13: 1 | AR13: 100 | AU13: 1
B14: 2 | C14: Traffic Management - (Loading/unloading/sheeting/temp. routes/speed/parking/competence) | K14: 0.03 | L14: 2 | S14: 15 | T14: Scaffolding - (Temp. Scaffolding Work-platform (All types) - qualified scaffolder / Inspection / Tagged / Safe Access/egress / PTW/Falsework & Formwork) | AB14: 0.04 | AC14: N/A | AP14: 2 | AR14: 75 | AU14: 2
